[2020-08-16 15:52:47 -0400] [14645] [DEBUG] Current configuration:
  child_exit: <function ChildExit.child_exit at 0x7617ea98>
  suppress_ragged_eofs: True
  config: None
  do_handshake_on_connect: False
  proc_name: None
  bind: ['0.0.0.0:10500']
  umask: 0
  logger_class: gunicorn.glogging.Logger
  reuse_port: False
  daemon: False
  initgroups: False
  paste: None
  pre_fork: <function Prefork.pre_fork at 0x7617e5d0>
  errorlog: gunicorn_error.log
  syslog_addr: udp://localhost:514
  syslog_prefix: None
  timeout: 120
  syslog: False
  preload_app: False
  user: 1000
  on_reload: <function OnReload.on_reload at 0x7617e468>
  max_requests_jitter: 0
  graceful_timeout: 30
  access_log_format: %(h)s %(l)s %(u)s %(t)s "%(r)s" %(s)s %(b)s "%(f)s" "%(a)s"
  raw_env: []
  pythonpath: None
  proxy_protocol: False
  reload_engine: auto
  proxy_allow_ips: ['127.0.0.1']
  keyfile: None
  ca_certs: None
  check_config: False
  accesslog: gunicorn_access.log
  workers: 1
  backlog: 2048
  disable_redirect_access_to_syslog: False
  syslog_facility: user
  worker_abort: <function WorkerAbort.worker_abort at 0x7617e858>
  pre_request: <function PreRequest.pre_request at 0x7617e978>
  worker_class: sync
  on_exit: <function OnExit.on_exit at 0x7617ec48>
  threads: 1
  on_starting: <function OnStarting.on_starting at 0x7617e3d8>
  dogstatsd_tags: 
  statsd_prefix: 
  nworkers_changed: <function NumWorkersChanged.nworkers_changed at 0x7617ebb8>
  limit_request_line: 4094
  keepalive: 2
  strip_header_spaces: False
  statsd_host: None
  reload: True
  forwarded_allow_ips: ['127.0.0.1']
  post_fork: <function Postfork.post_fork at 0x7617e660>
  raw_paste_global_conf: []
  limit_request_fields: 100
  ciphers: None
  reload_extra_files: []
  sendfile: None
  secure_scheme_headers: {'X-FORWARDED-PROTOCOL': 'ssl', 'X-FORWARDED-SSL': 'on', 'X-FORWARDED-PROTO': 'https'}
  max_requests: 0
  cert_reqs: 0
  pidfile: None
  loglevel: debug
  enable_stdio_inheritance: False
  worker_tmp_dir: None
  worker_int: <function WorkerInt.worker_int at 0x7617e7c8>
  post_request: <function PostRequest.post_request at 0x7617e9c0>
  logconfig_dict: {}
  chdir: /home/pi/Documents/pitemp/app
  post_worker_init: <function PostWorkerInit.post_worker_init at 0x7617e738>
  logconfig: None
  when_ready: <function WhenReady.when_ready at 0x7617e4f8>
  worker_connections: 1000
  ssl_version: 2
  worker_exit: <function WorkerExit.worker_exit at 0x7617eb28>
  limit_request_field_size: 8190
  certfile: None
  default_proc_name: pitemp_api
  group: 1000
  spew: False
  pre_exec: <function PreExec.pre_exec at 0x7617e8e8>
  tmp_upload_dir: None
  capture_output: False
[2020-08-16 15:52:47 -0400] [14645] [INFO] Starting gunicorn 20.0.4
[2020-08-16 15:52:47 -0400] [14645] [DEBUG] Arbiter booted
[2020-08-16 15:52:47 -0400] [14645] [INFO] Listening at: http://0.0.0.0:10500 (14645)
[2020-08-16 15:52:47 -0400] [14645] [INFO] Using worker: sync
[2020-08-16 15:52:47 -0400] [14663] [INFO] Booting worker with pid: 14663
[2020-08-16 15:52:47 -0400] [14645] [DEBUG] 1 workers
[2020-08-16 15:53:18 -0400] [14663] [DEBUG] GET /api/1.0/config
[2020-08-16 15:53:59 -0400] [14663] [DEBUG] GET /api/1.0/status
[2020-08-16 15:53:59,934] ERROR in app: Exception on /api/1.0/status [GET]
Traceback (most recent call last):
  File "/home/pi/Documents/pitemp/app/pitemp_api.py", line 28, in get_status
    system_status = pitemp_lib.get_system_status()
AttributeError: module 'pitemp_lib' has no attribute 'get_system_status'

During handling of the above exception, another exception occurred:

Traceback (most recent call last):
  File "/home/pi/.local/lib/python3.5/site-packages/flask/app.py", line 1982, in wsgi_app
    response = self.full_dispatch_request()
  File "/home/pi/.local/lib/python3.5/site-packages/flask/app.py", line 1614, in full_dispatch_request
    rv = self.handle_user_exception(e)
  File "/home/pi/.local/lib/python3.5/site-packages/flask/app.py", line 1517, in handle_user_exception
    reraise(exc_type, exc_value, tb)
  File "/home/pi/.local/lib/python3.5/site-packages/flask/_compat.py", line 33, in reraise
    raise value
  File "/home/pi/.local/lib/python3.5/site-packages/flask/app.py", line 1612, in full_dispatch_request
    rv = self.dispatch_request()
  File "/home/pi/.local/lib/python3.5/site-packages/flask/app.py", line 1598, in dispatch_request
    return self.view_functions[rule.endpoint](**req.view_args)
  File "/home/pi/Documents/pitemp/app/pitemp_api.py", line 30, in get_status
    logging.error("Sytem status: %s"%e)
NameError: name 'logging' is not defined
[2020-08-16 15:55:48 -0400] [14663] [INFO] Worker reloading: /home/pi/Documents/pitemp/app/pitemp_api.py modified
[2020-08-16 15:55:48 -0400] [14663] [INFO] Worker exiting (pid: 14663)
[2020-08-16 15:55:49 -0400] [14687] [INFO] Booting worker with pid: 14687
[2020-08-16 15:56:26 -0400] [14687] [INFO] Worker reloading: /home/pi/Documents/pitemp/app/pitemp_api.py modified
[2020-08-16 15:56:26 -0400] [14687] [INFO] Worker exiting (pid: 14687)
[2020-08-16 15:56:26 -0400] [14692] [INFO] Booting worker with pid: 14692
[2020-08-16 15:56:37 -0400] [14692] [DEBUG] GET /api/1.0/status
[2020-08-16 15:57:52 -0400] [14692] [INFO] Worker reloading: /home/pi/Documents/pitemp/app/pitemp_api.py modified
[2020-08-16 15:57:52 -0400] [14692] [INFO] Worker exiting (pid: 14692)
[2020-08-16 15:57:52 -0400] [14697] [INFO] Booting worker with pid: 14697
[2020-08-16 15:57:59 -0400] [14645] [INFO] Handling signal: int
[2020-08-16 15:58:00 -0400] [14697] [INFO] Worker exiting (pid: 14697)
[2020-08-16 15:58:00 -0400] [14645] [INFO] Shutting down: Master
[2020-08-16 15:58:03 -0400] [14703] [DEBUG] Current configuration:
  errorlog: gunicorn_error.log
  default_proc_name: pitemp_api
  capture_output: False
  syslog_addr: udp://localhost:514
  paste: None
  proxy_protocol: False
  spew: False
  ca_certs: None
  worker_class: sync
  graceful_timeout: 30
  limit_request_field_size: 8190
  worker_exit: <function WorkerExit.worker_exit at 0x761c3b28>
  logconfig: None
  enable_stdio_inheritance: False
  sendfile: None
  initgroups: False
  strip_header_spaces: False
  on_starting: <function OnStarting.on_starting at 0x761c33d8>
  accesslog: gunicorn_access.log
  dogstatsd_tags: 
  child_exit: <function ChildExit.child_exit at 0x761c3a98>
  on_exit: <function OnExit.on_exit at 0x761c3c48>
  config: None
  reload_engine: auto
  check_config: False
  worker_int: <function WorkerInt.worker_int at 0x761c37c8>
  certfile: None
  disable_redirect_access_to_syslog: False
  statsd_host: None
  max_requests: 0
  worker_tmp_dir: None
  pythonpath: None
  access_log_format: %(h)s %(l)s %(u)s %(t)s "%(r)s" %(s)s %(b)s "%(f)s" "%(a)s"
  logconfig_dict: {}
  syslog: False
  threads: 1
  timeout: 120
  keepalive: 2
  user: 1000
  post_fork: <function Postfork.post_fork at 0x761c3660>
  reload_extra_files: []
  ciphers: None
  limit_request_line: 4094
  preload_app: False
  chdir: /home/pi/Documents/pitemp/app
  backlog: 2048
  reuse_port: False
  keyfile: None
  daemon: False
  raw_env: []
  pidfile: None
  group: 1000
  umask: 0
  on_reload: <function OnReload.on_reload at 0x761c3468>
  pre_request: <function PreRequest.pre_request at 0x761c3978>
  post_request: <function PostRequest.post_request at 0x761c39c0>
  ssl_version: 2
  worker_connections: 1000
  forwarded_allow_ips: ['127.0.0.1']
  post_worker_init: <function PostWorkerInit.post_worker_init at 0x761c3738>
  pre_exec: <function PreExec.pre_exec at 0x761c38e8>
  cert_reqs: 0
  suppress_ragged_eofs: True
  loglevel: debug
  logger_class: gunicorn.glogging.Logger
  statsd_prefix: 
  secure_scheme_headers: {'X-FORWARDED-SSL': 'on', 'X-FORWARDED-PROTO': 'https', 'X-FORWARDED-PROTOCOL': 'ssl'}
  limit_request_fields: 100
  max_requests_jitter: 0
  bind: ['0.0.0.0:10500']
  tmp_upload_dir: None
  when_ready: <function WhenReady.when_ready at 0x761c34f8>
  raw_paste_global_conf: []
  worker_abort: <function WorkerAbort.worker_abort at 0x761c3858>
  syslog_prefix: None
  syslog_facility: user
  proxy_allow_ips: ['127.0.0.1']
  nworkers_changed: <function NumWorkersChanged.nworkers_changed at 0x761c3bb8>
  reload: True
  proc_name: None
  do_handshake_on_connect: False
  pre_fork: <function Prefork.pre_fork at 0x761c35d0>
  workers: 1
[2020-08-16 15:58:03 -0400] [14703] [INFO] Starting gunicorn 20.0.4
[2020-08-16 15:58:03 -0400] [14703] [DEBUG] Arbiter booted
[2020-08-16 15:58:03 -0400] [14703] [INFO] Listening at: http://0.0.0.0:10500 (14703)
[2020-08-16 15:58:03 -0400] [14703] [INFO] Using worker: sync
[2020-08-16 15:58:03 -0400] [14721] [INFO] Booting worker with pid: 14721
[2020-08-16 15:58:03 -0400] [14703] [DEBUG] 1 workers
[2020-08-16 15:58:15 -0400] [14721] [DEBUG] GET /api/1.0/status
[2020-08-16 15:58:15,817] ERROR in app: Exception on /api/1.0/status [GET]
Traceback (most recent call last):
  File "/home/pi/.local/lib/python3.5/site-packages/flask/app.py", line 1982, in wsgi_app
    response = self.full_dispatch_request()
  File "/home/pi/.local/lib/python3.5/site-packages/flask/app.py", line 1614, in full_dispatch_request
    rv = self.handle_user_exception(e)
  File "/home/pi/.local/lib/python3.5/site-packages/flask/app.py", line 1517, in handle_user_exception
    reraise(exc_type, exc_value, tb)
  File "/home/pi/.local/lib/python3.5/site-packages/flask/_compat.py", line 33, in reraise
    raise value
  File "/home/pi/.local/lib/python3.5/site-packages/flask/app.py", line 1612, in full_dispatch_request
    rv = self.dispatch_request()
  File "/home/pi/.local/lib/python3.5/site-packages/flask/app.py", line 1598, in dispatch_request
    return self.view_functions[rule.endpoint](**req.view_args)
  File "/home/pi/Documents/pitemp/app/pitemp_api.py", line 29, in get_status
    system_status = pitemp_lib.get_system_status()
AttributeError: module 'pitemp_lib' has no attribute 'get_system_status'
[2020-08-16 15:58:57 -0400] [14721] [INFO] Worker reloading: /home/pi/Documents/pitemp/app/pitemp_api.py modified
[2020-08-16 15:58:57 -0400] [14721] [INFO] Worker exiting (pid: 14721)
[2020-08-16 15:58:57 -0400] [14725] [INFO] Booting worker with pid: 14725
[2020-08-16 15:59:18 -0400] [14703] [INFO] Handling signal: int
[2020-08-16 15:59:18 -0400] [14725] [INFO] Worker exiting (pid: 14725)
[2020-08-16 15:59:18 -0400] [14703] [INFO] Shutting down: Master
[2020-08-16 15:59:22 -0400] [14730] [DEBUG] Current configuration:
  cert_reqs: 0
  default_proc_name: pitemp_api
  nworkers_changed: <function NumWorkersChanged.nworkers_changed at 0x76161bb8>
  ssl_version: 2
  post_request: <function PostRequest.post_request at 0x761619c0>
  chdir: /home/pi/Documents/pitemp/app
  bind: ['0.0.0.0:10500']
  on_reload: <function OnReload.on_reload at 0x76161468>
  certfile: None
  on_starting: <function OnStarting.on_starting at 0x761613d8>
  on_exit: <function OnExit.on_exit at 0x76161c48>
  max_requests_jitter: 0
  reuse_port: False
  pythonpath: None
  raw_paste_global_conf: []
  pre_fork: <function Prefork.pre_fork at 0x761615d0>
  worker_abort: <function WorkerAbort.worker_abort at 0x76161858>
  pre_exec: <function PreExec.pre_exec at 0x761618e8>
  timeout: 120
  keyfile: None
  sendfile: None
  worker_tmp_dir: None
  config: None
  do_handshake_on_connect: False
  dogstatsd_tags: 
  user: 1000
  threads: 1
  suppress_ragged_eofs: True
  syslog: False
  strip_header_spaces: False
  reload: True
  spew: False
  daemon: False
  umask: 0
  initgroups: False
  tmp_upload_dir: None
  child_exit: <function ChildExit.child_exit at 0x76161a98>
  limit_request_fields: 100
  capture_output: False
  syslog_prefix: None
  ca_certs: None
  proc_name: None
  syslog_facility: user
  ciphers: None
  disable_redirect_access_to_syslog: False
  logconfig_dict: {}
  pre_request: <function PreRequest.pre_request at 0x76161978>
  limit_request_field_size: 8190
  secure_scheme_headers: {'X-FORWARDED-PROTOCOL': 'ssl', 'X-FORWARDED-PROTO': 'https', 'X-FORWARDED-SSL': 'on'}
  reload_engine: auto
  paste: None
  limit_request_line: 4094
  access_log_format: %(h)s %(l)s %(u)s %(t)s "%(r)s" %(s)s %(b)s "%(f)s" "%(a)s"
  errorlog: gunicorn_error.log
  loglevel: debug
  logger_class: gunicorn.glogging.Logger
  workers: 1
  worker_class: sync
  worker_connections: 1000
  graceful_timeout: 30
  backlog: 2048
  pidfile: None
  forwarded_allow_ips: ['127.0.0.1']
  proxy_allow_ips: ['127.0.0.1']
  worker_int: <function WorkerInt.worker_int at 0x761617c8>
  enable_stdio_inheritance: False
  reload_extra_files: []
  check_config: False
  statsd_prefix: 
  when_ready: <function WhenReady.when_ready at 0x761614f8>
  post_worker_init: <function PostWorkerInit.post_worker_init at 0x76161738>
  worker_exit: <function WorkerExit.worker_exit at 0x76161b28>
  syslog_addr: udp://localhost:514
  keepalive: 2
  raw_env: []
  accesslog: gunicorn_access.log
  post_fork: <function Postfork.post_fork at 0x76161660>
  preload_app: False
  proxy_protocol: False
  logconfig: None
  statsd_host: None
  group: 1000
  max_requests: 0
[2020-08-16 15:59:22 -0400] [14730] [INFO] Starting gunicorn 20.0.4
[2020-08-16 15:59:22 -0400] [14730] [DEBUG] Arbiter booted
[2020-08-16 15:59:22 -0400] [14730] [INFO] Listening at: http://0.0.0.0:10500 (14730)
[2020-08-16 15:59:22 -0400] [14730] [INFO] Using worker: sync
[2020-08-16 15:59:22 -0400] [14748] [INFO] Booting worker with pid: 14748
[2020-08-16 15:59:22 -0400] [14730] [DEBUG] 1 workers
[2020-08-16 15:59:31 -0400] [14748] [DEBUG] GET /api/1.0/status
[2020-08-16 15:59:31,596] ERROR in app: Exception on /api/1.0/status [GET]
Traceback (most recent call last):
  File "/home/pi/.local/lib/python3.5/site-packages/flask/app.py", line 1982, in wsgi_app
    response = self.full_dispatch_request()
  File "/home/pi/.local/lib/python3.5/site-packages/flask/app.py", line 1614, in full_dispatch_request
    rv = self.handle_user_exception(e)
  File "/home/pi/.local/lib/python3.5/site-packages/flask/app.py", line 1517, in handle_user_exception
    reraise(exc_type, exc_value, tb)
  File "/home/pi/.local/lib/python3.5/site-packages/flask/_compat.py", line 33, in reraise
    raise value
  File "/home/pi/.local/lib/python3.5/site-packages/flask/app.py", line 1612, in full_dispatch_request
    rv = self.dispatch_request()
  File "/home/pi/.local/lib/python3.5/site-packages/flask/app.py", line 1598, in dispatch_request
    return self.view_functions[rule.endpoint](**req.view_args)
  File "/home/pi/Documents/pitemp/app/pitemp_api.py", line 29, in get_status
    system_status = pitemp_lib.get_system_status
AttributeError: module 'pitemp_lib' has no attribute 'get_system_status'
[2020-08-16 16:03:15 -0400] [14748] [INFO] Worker reloading: /home/pi/Documents/pitemp/app/pitemp_api.py modified
[2020-08-16 16:03:15 -0400] [14748] [INFO] Worker exiting (pid: 14748)
[2020-08-16 16:03:15 -0400] [14754] [INFO] Booting worker with pid: 14754
[2020-08-16 16:12:20 -0400] [14754] [INFO] Worker reloading: /home/pi/Documents/pitemp/app/pitemp_api.py modified
[2020-08-16 16:12:20 -0400] [14754] [INFO] Worker exiting (pid: 14754)
[2020-08-16 16:12:20 -0400] [14786] [INFO] Booting worker with pid: 14786
[2020-08-16 16:13:02 -0400] [14786] [DEBUG] GET /api/1.0/status
[2020-08-16 16:13:21 -0400] [14786] [DEBUG] GET /api/1.0/data
[2020-08-16 16:13:57 -0400] [14786] [INFO] Worker reloading: /home/pi/Documents/pitemp/app/pitemp_api.py modified
[2020-08-16 16:13:57 -0400] [14786] [INFO] Worker exiting (pid: 14786)
[2020-08-16 16:13:57 -0400] [14792] [INFO] Booting worker with pid: 14792
[2020-08-16 16:14:09 -0400] [14792] [DEBUG] GET /api/1.0/data
[2020-08-16 16:14:12 -0400] [14792] [DEBUG] GET /api/1.0/status
[2020-08-16 16:14:12,137] ERROR in app: Exception on /api/1.0/status [GET]
Traceback (most recent call last):
  File "/home/pi/.local/lib/python3.5/site-packages/flask/app.py", line 1982, in wsgi_app
    response = self.full_dispatch_request()
  File "/home/pi/.local/lib/python3.5/site-packages/flask/app.py", line 1614, in full_dispatch_request
    rv = self.handle_user_exception(e)
  File "/home/pi/.local/lib/python3.5/site-packages/flask/app.py", line 1517, in handle_user_exception
    reraise(exc_type, exc_value, tb)
  File "/home/pi/.local/lib/python3.5/site-packages/flask/_compat.py", line 33, in reraise
    raise value
  File "/home/pi/.local/lib/python3.5/site-packages/flask/app.py", line 1612, in full_dispatch_request
    rv = self.dispatch_request()
  File "/home/pi/.local/lib/python3.5/site-packages/flask/app.py", line 1598, in dispatch_request
    return self.view_functions[rule.endpoint](**req.view_args)
  File "/home/pi/Documents/pitemp/app/pitemp_api.py", line 29, in get_status
    system_status = pt.get_system_status()
TypeError: get_system_status() missing 1 required positional argument: 'self'
[2020-08-16 16:15:29 -0400] [14792] [INFO] Worker reloading: /home/pi/Documents/pitemp/app/pitemp_api.py modified
[2020-08-16 16:15:29 -0400] [14792] [INFO] Worker exiting (pid: 14792)
[2020-08-16 16:15:30 -0400] [14796] [INFO] Booting worker with pid: 14796
[2020-08-16 16:15:36 -0400] [14796] [DEBUG] GET /api/1.0/status
[2020-08-16 16:15:36,449] ERROR in app: Exception on /api/1.0/status [GET]
Traceback (most recent call last):
  File "/home/pi/.local/lib/python3.5/site-packages/flask/app.py", line 1982, in wsgi_app
    response = self.full_dispatch_request()
  File "/home/pi/.local/lib/python3.5/site-packages/flask/app.py", line 1614, in full_dispatch_request
    rv = self.handle_user_exception(e)
  File "/home/pi/.local/lib/python3.5/site-packages/flask/app.py", line 1517, in handle_user_exception
    reraise(exc_type, exc_value, tb)
  File "/home/pi/.local/lib/python3.5/site-packages/flask/_compat.py", line 33, in reraise
    raise value
  File "/home/pi/.local/lib/python3.5/site-packages/flask/app.py", line 1612, in full_dispatch_request
    rv = self.dispatch_request()
  File "/home/pi/.local/lib/python3.5/site-packages/flask/app.py", line 1598, in dispatch_request
    return self.view_functions[rule.endpoint](**req.view_args)
  File "/home/pi/Documents/pitemp/app/pitemp_api.py", line 30, in get_status
    system_status = pt.get_system_status()
  File "/home/pi/Documents/pitemp/app/pitemp_lib.py", line 205, in get_system_status
    cpu_stats = self.get_cpu_status()
  File "/home/pi/Documents/pitemp/app/pitemp_lib.py", line 141, in get_cpu_status
    for k,v in cmds.items:
TypeError: 'builtin_function_or_method' object is not iterable
[2020-08-18 20:54:12 -0400] [14730] [INFO] Handling signal: hup
[2020-08-18 20:54:12 -0400] [14730] [INFO] Hang up: Master
[2020-08-18 20:54:12 -0400] [14730] [DEBUG] Current configuration:
  cert_reqs: 0
  default_proc_name: pitemp_api
  nworkers_changed: <function NumWorkersChanged.nworkers_changed at 0x76161bb8>
  ssl_version: 2
  post_request: <function PostRequest.post_request at 0x761619c0>
  chdir: /home/pi/Documents/pitemp/app
  bind: ['0.0.0.0:10500']
  on_reload: <function OnReload.on_reload at 0x76161468>
  certfile: None
  on_starting: <function OnStarting.on_starting at 0x761613d8>
  on_exit: <function OnExit.on_exit at 0x76161c48>
  max_requests_jitter: 0
  reuse_port: False
  pythonpath: None
  raw_paste_global_conf: []
  pre_fork: <function Prefork.pre_fork at 0x761615d0>
  worker_abort: <function WorkerAbort.worker_abort at 0x76161858>
  pre_exec: <function PreExec.pre_exec at 0x761618e8>
  timeout: 120
  keyfile: None
  sendfile: None
  worker_tmp_dir: None
  config: None
  do_handshake_on_connect: False
  dogstatsd_tags: 
  user: 1000
  threads: 1
  suppress_ragged_eofs: True
  syslog: False
  strip_header_spaces: False
  reload: True
  spew: False
  daemon: False
  umask: 0
  initgroups: False
  tmp_upload_dir: None
  child_exit: <function ChildExit.child_exit at 0x76161a98>
  limit_request_fields: 100
  capture_output: False
  syslog_prefix: None
  ca_certs: None
  proc_name: None
  syslog_facility: user
  ciphers: None
  disable_redirect_access_to_syslog: False
  logconfig_dict: {}
  pre_request: <function PreRequest.pre_request at 0x76161978>
  limit_request_field_size: 8190
  secure_scheme_headers: {'X-FORWARDED-PROTOCOL': 'ssl', 'X-FORWARDED-PROTO': 'https', 'X-FORWARDED-SSL': 'on'}
  reload_engine: auto
  paste: None
  limit_request_line: 4094
  access_log_format: %(h)s %(l)s %(u)s %(t)s "%(r)s" %(s)s %(b)s "%(f)s" "%(a)s"
  errorlog: gunicorn_error.log
  loglevel: debug
  logger_class: gunicorn.glogging.Logger
  workers: 1
  worker_class: sync
  worker_connections: 1000
  graceful_timeout: 30
  backlog: 2048
  pidfile: None
  forwarded_allow_ips: ['127.0.0.1']
  proxy_allow_ips: ['127.0.0.1']
  worker_int: <function WorkerInt.worker_int at 0x761617c8>
  enable_stdio_inheritance: False
  reload_extra_files: []
  check_config: False
  statsd_prefix: 
  when_ready: <function WhenReady.when_ready at 0x761614f8>
  post_worker_init: <function PostWorkerInit.post_worker_init at 0x76161738>
  worker_exit: <function WorkerExit.worker_exit at 0x76161b28>
  syslog_addr: udp://localhost:514
  keepalive: 2
  raw_env: []
  accesslog: gunicorn_access.log
  post_fork: <function Postfork.post_fork at 0x76161660>
  preload_app: False
  proxy_protocol: False
  logconfig: None
  statsd_host: None
  group: 1000
  max_requests: 0
[2020-08-18 20:54:12 -0400] [14730] [INFO] Handling signal: hup
[2020-08-18 20:54:12 -0400] [14730] [INFO] Hang up: Master
[2020-08-18 20:54:12 -0400] [21633] [INFO] Booting worker with pid: 21633
[2020-08-18 20:54:12 -0400] [14730] [DEBUG] Current configuration:
  cert_reqs: 0
  default_proc_name: pitemp_api
  nworkers_changed: <function NumWorkersChanged.nworkers_changed at 0x76161bb8>
  ssl_version: 2
  post_request: <function PostRequest.post_request at 0x761619c0>
  chdir: /home/pi/Documents/pitemp/app
  bind: ['0.0.0.0:10500']
  on_reload: <function OnReload.on_reload at 0x76161468>
  certfile: None
  on_starting: <function OnStarting.on_starting at 0x761613d8>
  on_exit: <function OnExit.on_exit at 0x76161c48>
  max_requests_jitter: 0
  reuse_port: False
  pythonpath: None
  raw_paste_global_conf: []
  pre_fork: <function Prefork.pre_fork at 0x761615d0>
  worker_abort: <function WorkerAbort.worker_abort at 0x76161858>
  pre_exec: <function PreExec.pre_exec at 0x761618e8>
  timeout: 120
  keyfile: None
  sendfile: None
  worker_tmp_dir: None
  config: None
  do_handshake_on_connect: False
  dogstatsd_tags: 
  user: 1000
  threads: 1
  suppress_ragged_eofs: True
  syslog: False
  strip_header_spaces: False
  reload: True
  spew: False
  daemon: False
  umask: 0
  initgroups: False
  tmp_upload_dir: None
  child_exit: <function ChildExit.child_exit at 0x76161a98>
  limit_request_fields: 100
  capture_output: False
  syslog_prefix: None
  ca_certs: None
  proc_name: None
  syslog_facility: user
  ciphers: None
  disable_redirect_access_to_syslog: False
  logconfig_dict: {}
  pre_request: <function PreRequest.pre_request at 0x76161978>
  limit_request_field_size: 8190
  secure_scheme_headers: {'X-FORWARDED-PROTOCOL': 'ssl', 'X-FORWARDED-PROTO': 'https', 'X-FORWARDED-SSL': 'on'}
  reload_engine: auto
  paste: None
  limit_request_line: 4094
  access_log_format: %(h)s %(l)s %(u)s %(t)s "%(r)s" %(s)s %(b)s "%(f)s" "%(a)s"
  errorlog: gunicorn_error.log
  loglevel: debug
  logger_class: gunicorn.glogging.Logger
  workers: 1
  worker_class: sync
  worker_connections: 1000
  graceful_timeout: 30
  backlog: 2048
  pidfile: None
  forwarded_allow_ips: ['127.0.0.1']
  proxy_allow_ips: ['127.0.0.1']
  worker_int: <function WorkerInt.worker_int at 0x761617c8>
  enable_stdio_inheritance: False
  reload_extra_files: []
  check_config: False
  statsd_prefix: 
  when_ready: <function WhenReady.when_ready at 0x761614f8>
  post_worker_init: <function PostWorkerInit.post_worker_init at 0x76161738>
  worker_exit: <function WorkerExit.worker_exit at 0x76161b28>
  syslog_addr: udp://localhost:514
  keepalive: 2
  raw_env: []
  accesslog: gunicorn_access.log
  post_fork: <function Postfork.post_fork at 0x76161660>
  preload_app: False
  proxy_protocol: False
  logconfig: None
  statsd_host: None
  group: 1000
  max_requests: 0
[2020-08-18 20:54:12 -0400] [21634] [INFO] Booting worker with pid: 21634
[2020-08-18 20:54:13 -0400] [21633] [INFO] Worker exiting (pid: 21633)
[2020-08-18 21:07:16 -0400] [21634] [INFO] Worker reloading: /home/pi/Documents/pitemp/app/pitemp_lib.py modified
[2020-08-18 21:07:16 -0400] [21634] [INFO] Worker exiting (pid: 21634)
[2020-08-18 21:07:16 -0400] [21690] [INFO] Booting worker with pid: 21690
[2020-08-18 21:10:42 -0400] [21690] [DEBUG] GET /api/1.0/alive
[2020-08-18 21:11:02 -0400] [21690] [DEBUG] POST /api/1.0/alive
[2020-08-18 21:11:38 -0400] [21690] [DEBUG] GET /api/1.0/status
[2020-08-18 21:11:38,897] ERROR in app: Exception on /api/1.0/status [GET]
Traceback (most recent call last):
  File "/home/pi/.local/lib/python3.5/site-packages/flask/app.py", line 1982, in wsgi_app
    response = self.full_dispatch_request()
  File "/home/pi/.local/lib/python3.5/site-packages/flask/app.py", line 1614, in full_dispatch_request
    rv = self.handle_user_exception(e)
  File "/home/pi/.local/lib/python3.5/site-packages/flask/app.py", line 1517, in handle_user_exception
    reraise(exc_type, exc_value, tb)
  File "/home/pi/.local/lib/python3.5/site-packages/flask/_compat.py", line 33, in reraise
    raise value
  File "/home/pi/.local/lib/python3.5/site-packages/flask/app.py", line 1612, in full_dispatch_request
    rv = self.dispatch_request()
  File "/home/pi/.local/lib/python3.5/site-packages/flask/app.py", line 1598, in dispatch_request
    return self.view_functions[rule.endpoint](**req.view_args)
  File "/home/pi/Documents/pitemp/app/pitemp_api.py", line 30, in get_status
    system_status = pt.get_system_status()
  File "/home/pi/Documents/pitemp/app/pitemp_lib.py", line 210, in get_system_status
    cpu_stats = self.get_cpu_status()
  File "/home/pi/Documents/pitemp/app/pitemp_lib.py", line 146, in get_cpu_status
    for k,v in cmds.items:
TypeError: 'builtin_function_or_method' object is not iterable
[2020-08-18 21:12:34 -0400] [21690] [INFO] Worker reloading: /home/pi/Documents/pitemp/app/pitemp_lib.py modified
[2020-08-18 21:12:34 -0400] [21690] [INFO] Worker exiting (pid: 21690)
[2020-08-18 21:12:34 -0400] [21747] [INFO] Booting worker with pid: 21747
[2020-08-18 21:12:41 -0400] [21747] [DEBUG] GET /api/1.0/status
[2020-08-18 21:12:42,021] ERROR in app: Exception on /api/1.0/status [GET]
Traceback (most recent call last):
  File "/home/pi/.local/lib/python3.5/site-packages/flask/app.py", line 1982, in wsgi_app
    response = self.full_dispatch_request()
  File "/home/pi/.local/lib/python3.5/site-packages/flask/app.py", line 1614, in full_dispatch_request
    rv = self.handle_user_exception(e)
  File "/home/pi/.local/lib/python3.5/site-packages/flask/app.py", line 1517, in handle_user_exception
    reraise(exc_type, exc_value, tb)
  File "/home/pi/.local/lib/python3.5/site-packages/flask/_compat.py", line 33, in reraise
    raise value
  File "/home/pi/.local/lib/python3.5/site-packages/flask/app.py", line 1612, in full_dispatch_request
    rv = self.dispatch_request()
  File "/home/pi/.local/lib/python3.5/site-packages/flask/app.py", line 1598, in dispatch_request
    return self.view_functions[rule.endpoint](**req.view_args)
  File "/home/pi/Documents/pitemp/app/pitemp_api.py", line 30, in get_status
    system_status = pt.get_system_status()
  File "/home/pi/Documents/pitemp/app/pitemp_lib.py", line 211, in get_system_status
    system_mem = self.get_memory()
  File "/home/pi/Documents/pitemp/app/pitemp_lib.py", line 186, in get_memory
    for k,v in cmds.items:
TypeError: 'builtin_function_or_method' object is not iterable
[2020-08-18 21:15:04 -0400] [21747] [INFO] Worker reloading: /home/pi/Documents/pitemp/app/pitemp_lib.py modified
[2020-08-18 21:15:04 -0400] [21747] [INFO] Worker exiting (pid: 21747)
[2020-08-18 21:15:04 -0400] [21766] [INFO] Booting worker with pid: 21766
[2020-08-18 21:15:08 -0400] [21766] [DEBUG] GET /api/1.0/status
[2020-08-18 21:15:08,171] ERROR in app: Exception on /api/1.0/status [GET]
Traceback (most recent call last):
  File "/home/pi/.local/lib/python3.5/site-packages/flask/app.py", line 1982, in wsgi_app
    response = self.full_dispatch_request()
  File "/home/pi/.local/lib/python3.5/site-packages/flask/app.py", line 1614, in full_dispatch_request
    rv = self.handle_user_exception(e)
  File "/home/pi/.local/lib/python3.5/site-packages/flask/app.py", line 1517, in handle_user_exception
    reraise(exc_type, exc_value, tb)
  File "/home/pi/.local/lib/python3.5/site-packages/flask/_compat.py", line 33, in reraise
    raise value
  File "/home/pi/.local/lib/python3.5/site-packages/flask/app.py", line 1612, in full_dispatch_request
    rv = self.dispatch_request()
  File "/home/pi/.local/lib/python3.5/site-packages/flask/app.py", line 1598, in dispatch_request
    return self.view_functions[rule.endpoint](**req.view_args)
  File "/home/pi/Documents/pitemp/app/pitemp_api.py", line 30, in get_status
    system_status = pt.get_system_status()
  File "/home/pi/Documents/pitemp/app/pitemp_lib.py", line 210, in get_system_status
    cpu_stats = self.get_cpu_status()
  File "/home/pi/Documents/pitemp/app/pitemp_lib.py", line 146, in get_cpu_status
    for k,v in cmds.iteritems():
AttributeError: 'dict' object has no attribute 'iteritems'
[2020-08-18 21:16:34 -0400] [21766] [INFO] Worker reloading: /home/pi/Documents/pitemp/app/pitemp_lib.py modified
[2020-08-18 21:16:34 -0400] [21766] [INFO] Worker exiting (pid: 21766)
[2020-08-18 21:16:35 -0400] [21772] [INFO] Booting worker with pid: 21772
[2020-08-18 21:16:38 -0400] [21772] [DEBUG] GET /api/1.0/status
[2020-08-18 21:16:38,493] ERROR in app: Exception on /api/1.0/status [GET]
Traceback (most recent call last):
  File "/home/pi/.local/lib/python3.5/site-packages/flask/app.py", line 1982, in wsgi_app
    response = self.full_dispatch_request()
  File "/home/pi/.local/lib/python3.5/site-packages/flask/app.py", line 1614, in full_dispatch_request
    rv = self.handle_user_exception(e)
  File "/home/pi/.local/lib/python3.5/site-packages/flask/app.py", line 1517, in handle_user_exception
    reraise(exc_type, exc_value, tb)
  File "/home/pi/.local/lib/python3.5/site-packages/flask/_compat.py", line 33, in reraise
    raise value
  File "/home/pi/.local/lib/python3.5/site-packages/flask/app.py", line 1612, in full_dispatch_request
    rv = self.dispatch_request()
  File "/home/pi/.local/lib/python3.5/site-packages/flask/app.py", line 1598, in dispatch_request
    return self.view_functions[rule.endpoint](**req.view_args)
  File "/home/pi/Documents/pitemp/app/pitemp_api.py", line 30, in get_status
    system_status = pt.get_system_status()
  File "/home/pi/Documents/pitemp/app/pitemp_lib.py", line 212, in get_system_status
    system_mem = self.get_memory()
  File "/home/pi/Documents/pitemp/app/pitemp_lib.py", line 187, in get_memory
    for k,v in cmds.items:
TypeError: 'builtin_function_or_method' object is not iterable
[2020-08-18 21:18:21 -0400] [21772] [INFO] Worker reloading: /home/pi/Documents/pitemp/app/pitemp_lib.py modified
[2020-08-18 21:18:21 -0400] [21772] [INFO] Worker exiting (pid: 21772)
[2020-08-18 21:18:22 -0400] [21791] [INFO] Booting worker with pid: 21791
[2020-08-18 21:18:22 -0400] [21791] [ERROR] unexpected indent (pitemp_lib.py, line 225)
Traceback (most recent call last):
  File "/home/pi/.local/lib/python3.5/site-packages/gunicorn/workers/base.py", line 144, in load_wsgi
    self.wsgi = self.app.wsgi()
  File "/home/pi/.local/lib/python3.5/site-packages/gunicorn/app/base.py", line 67, in wsgi
    self.callable = self.load()
  File "/home/pi/.local/lib/python3.5/site-packages/gunicorn/app/wsgiapp.py", line 49, in load
    return self.load_wsgiapp()
  File "/home/pi/.local/lib/python3.5/site-packages/gunicorn/app/wsgiapp.py", line 39, in load_wsgiapp
    return util.import_app(self.app_uri)
  File "/home/pi/.local/lib/python3.5/site-packages/gunicorn/util.py", line 358, in import_app
    mod = importlib.import_module(module)
  File "/usr/lib/python3.5/importlib/__init__.py", line 126, in import_module
    return _bootstrap._gcd_import(name[level:], package, level)
  File "<frozen importlib._bootstrap>", line 986, in _gcd_import
  File "<frozen importlib._bootstrap>", line 969, in _find_and_load
  File "<frozen importlib._bootstrap>", line 958, in _find_and_load_unlocked
  File "<frozen importlib._bootstrap>", line 673, in _load_unlocked
  File "<frozen importlib._bootstrap_external>", line 673, in exec_module
  File "<frozen importlib._bootstrap>", line 222, in _call_with_frames_removed
  File "/home/pi/Documents/pitemp/app/pitemp_api.py", line 2, in <module>
    from pitemp_lib import pitemp
  File "/home/pi/Documents/pitemp/app/pitemp_lib.py", line 225
    return "abbadoo"
    ^
IndentationError: unexpected indent
[2020-08-18 21:18:22 -0400] [21791] [ERROR] Exception in worker process
Traceback (most recent call last):
  File "/home/pi/.local/lib/python3.5/site-packages/gunicorn/workers/base.py", line 144, in load_wsgi
    self.wsgi = self.app.wsgi()
  File "/home/pi/.local/lib/python3.5/site-packages/gunicorn/app/base.py", line 67, in wsgi
    self.callable = self.load()
  File "/home/pi/.local/lib/python3.5/site-packages/gunicorn/app/wsgiapp.py", line 49, in load
    return self.load_wsgiapp()
  File "/home/pi/.local/lib/python3.5/site-packages/gunicorn/app/wsgiapp.py", line 39, in load_wsgiapp
    return util.import_app(self.app_uri)
  File "/home/pi/.local/lib/python3.5/site-packages/gunicorn/util.py", line 358, in import_app
    mod = importlib.import_module(module)
  File "/usr/lib/python3.5/importlib/__init__.py", line 126, in import_module
    return _bootstrap._gcd_import(name[level:], package, level)
  File "<frozen importlib._bootstrap>", line 986, in _gcd_import
  File "<frozen importlib._bootstrap>", line 969, in _find_and_load
  File "<frozen importlib._bootstrap>", line 958, in _find_and_load_unlocked
  File "<frozen importlib._bootstrap>", line 673, in _load_unlocked
  File "<frozen importlib._bootstrap_external>", line 673, in exec_module
  File "<frozen importlib._bootstrap>", line 222, in _call_with_frames_removed
  File "/home/pi/Documents/pitemp/app/pitemp_api.py", line 2, in <module>
    from pitemp_lib import pitemp
  File "/home/pi/Documents/pitemp/app/pitemp_lib.py", line 225
    return "abbadoo"
    ^
IndentationError: unexpected indent

During handling of the above exception, another exception occurred:

Traceback (most recent call last):
  File "/home/pi/.local/lib/python3.5/site-packages/gunicorn/arbiter.py", line 583, in spawn_worker
    worker.init_process()
  File "/home/pi/.local/lib/python3.5/site-packages/gunicorn/workers/base.py", line 119, in init_process
    self.load_wsgi()
  File "/home/pi/.local/lib/python3.5/site-packages/gunicorn/workers/base.py", line 157, in load_wsgi
    self.reloader.add_extra_file(exc_val.filename)
AttributeError: 'NoneType' object has no attribute 'add_extra_file'
[2020-08-18 21:18:22 -0400] [21791] [INFO] Worker exiting (pid: 21791)
[2020-08-18 21:18:22 -0400] [14730] [INFO] Shutting down: Master
[2020-08-18 21:18:22 -0400] [14730] [INFO] Reason: Worker failed to boot.
[2020-08-18 21:20:44 -0400] [21826] [DEBUG] Current configuration:
  nworkers_changed: <function NumWorkersChanged.nworkers_changed at 0x761e3bb8>
  syslog: False
  graceful_timeout: 30
  pythonpath: None
  accesslog: gunicorn_access.log
  limit_request_line: 4094
  worker_connections: 1000
  tmp_upload_dir: None
  check_config: False
  preload_app: False
  max_requests_jitter: 0
  proxy_allow_ips: ['127.0.0.1']
  syslog_facility: user
  dogstatsd_tags: 
  timeout: 120
  pre_fork: <function Prefork.pre_fork at 0x761e35d0>
  post_fork: <function Postfork.post_fork at 0x761e3660>
  worker_int: <function WorkerInt.worker_int at 0x761e37c8>
  statsd_prefix: 
  default_proc_name: pitemp_api
  umask: 0
  strip_header_spaces: False
  reload_extra_files: []
  backlog: 2048
  worker_abort: <function WorkerAbort.worker_abort at 0x761e3858>
  pre_exec: <function PreExec.pre_exec at 0x761e38e8>
  child_exit: <function ChildExit.child_exit at 0x761e3a98>
  threads: 1
  limit_request_field_size: 8190
  user: 1000
  ca_certs: None
  worker_exit: <function WorkerExit.worker_exit at 0x761e3b28>
  cert_reqs: 0
  logconfig_dict: {}
  do_handshake_on_connect: False
  sendfile: None
  limit_request_fields: 100
  worker_tmp_dir: None
  initgroups: False
  config: None
  when_ready: <function WhenReady.when_ready at 0x761e34f8>
  keepalive: 2
  on_reload: <function OnReload.on_reload at 0x761e3468>
  raw_env: []
  pre_request: <function PreRequest.pre_request at 0x761e3978>
  workers: 1
  keyfile: None
  suppress_ragged_eofs: True
  access_log_format: %(h)s %(l)s %(u)s %(t)s "%(r)s" %(s)s %(b)s "%(f)s" "%(a)s"
  syslog_prefix: None
  on_starting: <function OnStarting.on_starting at 0x761e33d8>
  ciphers: None
  errorlog: gunicorn_error.log
  max_requests: 0
  disable_redirect_access_to_syslog: False
  loglevel: debug
  enable_stdio_inheritance: False
  chdir: /home/pi/Documents/pitemp/app
  daemon: False
  paste: None
  capture_output: False
  post_request: <function PostRequest.post_request at 0x761e39c0>
  group: 1000
  worker_class: sync
  syslog_addr: udp://localhost:514
  statsd_host: None
  proc_name: None
  reuse_port: False
  secure_scheme_headers: {'X-FORWARDED-PROTO': 'https', 'X-FORWARDED-SSL': 'on', 'X-FORWARDED-PROTOCOL': 'ssl'}
  forwarded_allow_ips: ['127.0.0.1']
  proxy_protocol: False
  on_exit: <function OnExit.on_exit at 0x761e3c48>
  reload: True
  spew: False
  certfile: None
  logger_class: gunicorn.glogging.Logger
  logconfig: None
  pidfile: None
  post_worker_init: <function PostWorkerInit.post_worker_init at 0x761e3738>
  raw_paste_global_conf: []
  bind: ['0.0.0.0:10500']
  reload_engine: auto
  ssl_version: 2
[2020-08-18 21:20:44 -0400] [21826] [INFO] Starting gunicorn 20.0.4
[2020-08-18 21:20:44 -0400] [21826] [DEBUG] Arbiter booted
[2020-08-18 21:20:44 -0400] [21826] [INFO] Listening at: http://0.0.0.0:10500 (21826)
[2020-08-18 21:20:44 -0400] [21826] [INFO] Using worker: sync
[2020-08-18 21:20:44 -0400] [21830] [INFO] Booting worker with pid: 21830
[2020-08-18 21:20:44 -0400] [21830] [ERROR] Exception in worker process
Traceback (most recent call last):
  File "/home/pi/.local/lib/python3.5/site-packages/gunicorn/arbiter.py", line 583, in spawn_worker
    worker.init_process()
  File "/home/pi/.local/lib/python3.5/site-packages/gunicorn/workers/base.py", line 119, in init_process
    self.load_wsgi()
  File "/home/pi/.local/lib/python3.5/site-packages/gunicorn/workers/base.py", line 144, in load_wsgi
    self.wsgi = self.app.wsgi()
  File "/home/pi/.local/lib/python3.5/site-packages/gunicorn/app/base.py", line 67, in wsgi
    self.callable = self.load()
  File "/home/pi/.local/lib/python3.5/site-packages/gunicorn/app/wsgiapp.py", line 49, in load
    return self.load_wsgiapp()
  File "/home/pi/.local/lib/python3.5/site-packages/gunicorn/app/wsgiapp.py", line 39, in load_wsgiapp
    return util.import_app(self.app_uri)
  File "/home/pi/.local/lib/python3.5/site-packages/gunicorn/util.py", line 358, in import_app
    mod = importlib.import_module(module)
  File "/usr/lib/python3.5/importlib/__init__.py", line 126, in import_module
    return _bootstrap._gcd_import(name[level:], package, level)
  File "<frozen importlib._bootstrap>", line 986, in _gcd_import
  File "<frozen importlib._bootstrap>", line 969, in _find_and_load
  File "<frozen importlib._bootstrap>", line 958, in _find_and_load_unlocked
  File "<frozen importlib._bootstrap>", line 673, in _load_unlocked
  File "<frozen importlib._bootstrap_external>", line 673, in exec_module
  File "<frozen importlib._bootstrap>", line 222, in _call_with_frames_removed
  File "/home/pi/Documents/pitemp/app/pitemp_api.py", line 1, in <module>
    import settings
  File "/home/pi/Documents/pitemp/app/settings.py", line 20, in <module>
    PINS = PINS.split(',')
AttributeError: 'NoneType' object has no attribute 'split'
[2020-08-18 21:20:44 -0400] [21830] [INFO] Worker exiting (pid: 21830)
[2020-08-18 21:20:44 -0400] [21826] [DEBUG] 1 workers
[2020-08-18 21:20:44 -0400] [21826] [INFO] Shutting down: Master
[2020-08-18 21:20:44 -0400] [21826] [INFO] Reason: Worker failed to boot.
[2020-08-18 21:20:54 -0400] [21837] [DEBUG] Current configuration:
  on_exit: <function OnExit.on_exit at 0x761a5c48>
  ssl_version: 2
  logconfig_dict: {}
  spew: False
  chdir: /home/pi/Documents/pitemp/app
  pidfile: None
  pythonpath: None
  workers: 1
  max_requests_jitter: 0
  reload_engine: auto
  capture_output: False
  syslog: False
  dogstatsd_tags: 
  statsd_prefix: 
  worker_tmp_dir: None
  user: 1000
  tmp_upload_dir: None
  forwarded_allow_ips: ['127.0.0.1']
  proxy_protocol: False
  post_fork: <function Postfork.post_fork at 0x761a5660>
  pre_exec: <function PreExec.pre_exec at 0x761a58e8>
  reload_extra_files: []
  pre_request: <function PreRequest.pre_request at 0x761a5978>
  timeout: 120
  logger_class: gunicorn.glogging.Logger
  syslog_facility: user
  reload: True
  limit_request_line: 4094
  config: None
  check_config: False
  threads: 1
  pre_fork: <function Prefork.pre_fork at 0x761a55d0>
  worker_int: <function WorkerInt.worker_int at 0x761a57c8>
  limit_request_field_size: 8190
  bind: ['0.0.0.0:10500']
  backlog: 2048
  logconfig: None
  syslog_prefix: None
  post_request: <function PostRequest.post_request at 0x761a59c0>
  worker_exit: <function WorkerExit.worker_exit at 0x761a5b28>
  preload_app: False
  sendfile: None
  errorlog: gunicorn_error.log
  worker_abort: <function WorkerAbort.worker_abort at 0x761a5858>
  worker_class: sync
  daemon: False
  post_worker_init: <function PostWorkerInit.post_worker_init at 0x761a5738>
  reuse_port: False
  do_handshake_on_connect: False
  access_log_format: %(h)s %(l)s %(u)s %(t)s "%(r)s" %(s)s %(b)s "%(f)s" "%(a)s"
  statsd_host: None
  cert_reqs: 0
  proc_name: None
  secure_scheme_headers: {'X-FORWARDED-PROTO': 'https', 'X-FORWARDED-PROTOCOL': 'ssl', 'X-FORWARDED-SSL': 'on'}
  proxy_allow_ips: ['127.0.0.1']
  enable_stdio_inheritance: False
  when_ready: <function WhenReady.when_ready at 0x761a54f8>
  keyfile: None
  max_requests: 0
  default_proc_name: pitemp_api
  raw_env: []
  initgroups: False
  strip_header_spaces: False
  keepalive: 2
  on_starting: <function OnStarting.on_starting at 0x761a53d8>
  loglevel: debug
  on_reload: <function OnReload.on_reload at 0x761a5468>
  nworkers_changed: <function NumWorkersChanged.nworkers_changed at 0x761a5bb8>
  syslog_addr: udp://localhost:514
  suppress_ragged_eofs: True
  ciphers: None
  child_exit: <function ChildExit.child_exit at 0x761a5a98>
  graceful_timeout: 30
  paste: None
  raw_paste_global_conf: []
  disable_redirect_access_to_syslog: False
  certfile: None
  ca_certs: None
  worker_connections: 1000
  group: 1000
  umask: 0
  limit_request_fields: 100
  accesslog: gunicorn_access.log
[2020-08-18 21:20:54 -0400] [21837] [INFO] Starting gunicorn 20.0.4
[2020-08-18 21:20:54 -0400] [21837] [DEBUG] Arbiter booted
[2020-08-18 21:20:54 -0400] [21837] [INFO] Listening at: http://0.0.0.0:10500 (21837)
[2020-08-18 21:20:54 -0400] [21837] [INFO] Using worker: sync
[2020-08-18 21:20:54 -0400] [21855] [INFO] Booting worker with pid: 21855
[2020-08-18 21:20:54 -0400] [21837] [DEBUG] 1 workers
[2020-08-18 21:21:59 -0400] [21855] [DEBUG] GET /api/1.0/status
[2020-08-18 21:23:50 -0400] [21855] [INFO] Worker reloading: /home/pi/Documents/pitemp/app/pitemp_api.py modified
[2020-08-18 21:23:50 -0400] [21855] [INFO] Worker exiting (pid: 21855)
[2020-08-18 21:23:50 -0400] [21903] [INFO] Booting worker with pid: 21903
[2020-08-18 21:23:55 -0400] [21903] [DEBUG] GET /api/1.0/status
[2020-08-18 21:24:28 -0400] [21903] [INFO] Worker reloading: /home/pi/Documents/pitemp/app/pitemp_lib.py modified
[2020-08-18 21:24:28 -0400] [21903] [INFO] Worker exiting (pid: 21903)
[2020-08-18 21:24:28 -0400] [21909] [INFO] Booting worker with pid: 21909
[2020-08-18 21:24:36 -0400] [21909] [DEBUG] GET /api/1.0/status
[2020-08-18 21:26:09 -0400] [21909] [INFO] Worker reloading: /home/pi/Documents/pitemp/app/pitemp_lib.py modified
[2020-08-18 21:26:09 -0400] [21909] [INFO] Worker exiting (pid: 21909)
[2020-08-18 21:26:09 -0400] [21914] [INFO] Booting worker with pid: 21914
[2020-08-18 21:26:17 -0400] [21914] [DEBUG] GET /api/1.0/status
[2020-08-18 21:26:36 -0400] [21914] [INFO] Worker reloading: /home/pi/Documents/pitemp/app/pitemp_lib.py modified
[2020-08-18 21:26:36 -0400] [21914] [INFO] Worker exiting (pid: 21914)
[2020-08-18 21:26:36 -0400] [21931] [INFO] Booting worker with pid: 21931
[2020-08-18 21:26:40 -0400] [21931] [DEBUG] GET /api/1.0/status
[2020-08-18 21:27:08 -0400] [21931] [INFO] Worker reloading: /home/pi/Documents/pitemp/app/pitemp_lib.py modified
[2020-08-18 21:27:08 -0400] [21931] [INFO] Worker exiting (pid: 21931)
[2020-08-18 21:27:09 -0400] [21947] [INFO] Booting worker with pid: 21947
[2020-08-18 21:27:13 -0400] [21947] [DEBUG] GET /api/1.0/status
[2020-08-18 21:28:12 -0400] [21947] [INFO] Worker reloading: /home/pi/Documents/pitemp/app/pitemp_lib.py modified
[2020-08-18 21:28:12 -0400] [21947] [INFO] Worker exiting (pid: 21947)
[2020-08-18 21:28:12 -0400] [21965] [INFO] Booting worker with pid: 21965
[2020-08-18 21:28:19 -0400] [21965] [DEBUG] GET /api/1.0/status
[2020-08-18 21:43:46 -0400] [21965] [INFO] Worker reloading: /home/pi/Documents/pitemp/app/pitemp_lib.py modified
[2020-08-18 21:43:46 -0400] [21965] [INFO] Worker exiting (pid: 21965)
[2020-08-18 21:43:46 -0400] [22056] [INFO] Booting worker with pid: 22056
[2020-08-18 21:45:19 -0400] [22056] [INFO] Worker reloading: /home/pi/Documents/pitemp/app/pitemp_lib.py modified
[2020-08-18 21:45:19 -0400] [22056] [INFO] Worker exiting (pid: 22056)
[2020-08-18 21:45:20 -0400] [22063] [INFO] Booting worker with pid: 22063
[2020-08-18 21:50:37 -0400] [22063] [INFO] Worker reloading: /home/pi/Documents/pitemp/app/pitemp_lib.py modified
[2020-08-18 21:50:37 -0400] [22063] [INFO] Worker exiting (pid: 22063)
[2020-08-18 21:50:37 -0400] [22087] [INFO] Booting worker with pid: 22087
[2020-08-18 21:50:45 -0400] [22087] [DEBUG] GET /api/1.0/status
[2020-08-18 21:51:26 -0400] [22087] [INFO] Worker reloading: /home/pi/Documents/pitemp/app/pitemp_lib.py modified
[2020-08-18 21:51:26 -0400] [22087] [INFO] Worker exiting (pid: 22087)
[2020-08-18 21:51:26 -0400] [22104] [INFO] Booting worker with pid: 22104
[2020-08-18 21:51:33 -0400] [22104] [DEBUG] GET /api/1.0/status
[2020-08-18 21:52:51 -0400] [22104] [INFO] Worker reloading: /home/pi/Documents/pitemp/app/pitemp_lib.py modified
[2020-08-18 21:52:51 -0400] [22104] [INFO] Worker exiting (pid: 22104)
[2020-08-18 21:52:51 -0400] [22121] [INFO] Booting worker with pid: 22121
[2020-08-18 21:53:05 -0400] [22121] [DEBUG] GET /api/1.0/status
[2020-08-18 21:55:02 -0400] [22121] [INFO] Worker reloading: /home/pi/Documents/pitemp/app/pitemp_lib.py modified
[2020-08-18 21:55:02 -0400] [22121] [INFO] Worker exiting (pid: 22121)
[2020-08-18 21:55:02 -0400] [22139] [INFO] Booting worker with pid: 22139
[2020-08-18 21:55:52 -0400] [22139] [INFO] Worker reloading: /home/pi/Documents/pitemp/app/pitemp_api.py modified
[2020-08-18 21:55:52 -0400] [22139] [INFO] Worker exiting (pid: 22139)
[2020-08-18 21:55:52 -0400] [22145] [INFO] Booting worker with pid: 22145
[2020-08-18 21:56:00 -0400] [22145] [DEBUG] GET /api/1.0/status
[2020-08-18 21:56:00,765] ERROR in app: Exception on /api/1.0/status [GET]
Traceback (most recent call last):
  File "/home/pi/.local/lib/python3.5/site-packages/flask/app.py", line 1982, in wsgi_app
    response = self.full_dispatch_request()
  File "/home/pi/.local/lib/python3.5/site-packages/flask/app.py", line 1614, in full_dispatch_request
    rv = self.handle_user_exception(e)
  File "/home/pi/.local/lib/python3.5/site-packages/flask/app.py", line 1517, in handle_user_exception
    reraise(exc_type, exc_value, tb)
  File "/home/pi/.local/lib/python3.5/site-packages/flask/_compat.py", line 33, in reraise
    raise value
  File "/home/pi/.local/lib/python3.5/site-packages/flask/app.py", line 1612, in full_dispatch_request
    rv = self.dispatch_request()
  File "/home/pi/.local/lib/python3.5/site-packages/flask/app.py", line 1598, in dispatch_request
    return self.view_functions[rule.endpoint](**req.view_args)
  File "/home/pi/Documents/pitemp/app/pitemp_api.py", line 30, in get_status
    system_status = pt.get_system_status()
  File "/home/pi/Documents/pitemp/app/pitemp_lib.py", line 213, in get_system_status
    system_mem = self.get_memory()
  File "/home/pi/Documents/pitemp/app/pitemp_lib.py", line 188, in get_memory
    for k,v in cmds.items:
TypeError: 'builtin_function_or_method' object is not iterable
[2020-08-18 21:57:40 -0400] [22145] [INFO] Worker reloading: /home/pi/Documents/pitemp/app/pitemp_lib.py modified
[2020-08-18 21:57:40 -0400] [22145] [INFO] Worker exiting (pid: 22145)
[2020-08-18 21:57:40 -0400] [22174] [INFO] Booting worker with pid: 22174
[2020-08-18 21:58:03 -0400] [22174] [DEBUG] GET /api/1.0/status
[2020-08-18 21:58:03,231] ERROR in app: Exception on /api/1.0/status [GET]
Traceback (most recent call last):
  File "/home/pi/.local/lib/python3.5/site-packages/flask/app.py", line 1982, in wsgi_app
    response = self.full_dispatch_request()
  File "/home/pi/.local/lib/python3.5/site-packages/flask/app.py", line 1614, in full_dispatch_request
    rv = self.handle_user_exception(e)
  File "/home/pi/.local/lib/python3.5/site-packages/flask/app.py", line 1517, in handle_user_exception
    reraise(exc_type, exc_value, tb)
  File "/home/pi/.local/lib/python3.5/site-packages/flask/_compat.py", line 33, in reraise
    raise value
  File "/home/pi/.local/lib/python3.5/site-packages/flask/app.py", line 1612, in full_dispatch_request
    rv = self.dispatch_request()
  File "/home/pi/.local/lib/python3.5/site-packages/flask/app.py", line 1598, in dispatch_request
    return self.view_functions[rule.endpoint](**req.view_args)
  File "/home/pi/Documents/pitemp/app/pitemp_api.py", line 30, in get_status
    system_status = pt.get_system_status()
  File "/home/pi/Documents/pitemp/app/pitemp_lib.py", line 213, in get_system_status
    system_mem = self.get_memory()
  File "/home/pi/Documents/pitemp/app/pitemp_lib.py", line 187, in get_memory
    for k,v in cmds.items:
TypeError: 'builtin_function_or_method' object is not iterable
[2020-08-18 21:58:29 -0400] [22174] [INFO] Worker reloading: /home/pi/Documents/pitemp/app/pitemp_lib.py modified
[2020-08-18 21:58:29 -0400] [22174] [INFO] Worker exiting (pid: 22174)
[2020-08-18 21:58:29 -0400] [22191] [INFO] Booting worker with pid: 22191
[2020-08-18 21:58:55 -0400] [22191] [DEBUG] GET /api/1.0/status
[2020-08-18 21:58:55,350] ERROR in app: Exception on /api/1.0/status [GET]
Traceback (most recent call last):
  File "/home/pi/.local/lib/python3.5/site-packages/flask/app.py", line 1982, in wsgi_app
    response = self.full_dispatch_request()
  File "/home/pi/.local/lib/python3.5/site-packages/flask/app.py", line 1614, in full_dispatch_request
    rv = self.handle_user_exception(e)
  File "/home/pi/.local/lib/python3.5/site-packages/flask/app.py", line 1517, in handle_user_exception
    reraise(exc_type, exc_value, tb)
  File "/home/pi/.local/lib/python3.5/site-packages/flask/_compat.py", line 33, in reraise
    raise value
  File "/home/pi/.local/lib/python3.5/site-packages/flask/app.py", line 1612, in full_dispatch_request
    rv = self.dispatch_request()
  File "/home/pi/.local/lib/python3.5/site-packages/flask/app.py", line 1598, in dispatch_request
    return self.view_functions[rule.endpoint](**req.view_args)
  File "/home/pi/Documents/pitemp/app/pitemp_api.py", line 30, in get_status
    system_status = pt.get_system_status()
  File "/home/pi/Documents/pitemp/app/pitemp_lib.py", line 217, in get_system_status
    'cpu_temp':cpu_stats['cpu_temp'],
KeyError: 'cpu_temp'
[2020-08-18 22:00:53 -0400] [22191] [INFO] Worker reloading: /home/pi/Documents/pitemp/app/pitemp_lib.py modified
[2020-08-18 22:00:53 -0400] [22191] [INFO] Worker exiting (pid: 22191)
[2020-08-18 22:00:53 -0400] [22218] [INFO] Booting worker with pid: 22218
[2020-08-18 22:00:59 -0400] [22218] [DEBUG] GET /api/1.0/status
[2020-08-18 22:00:59,653] ERROR in app: Exception on /api/1.0/status [GET]
Traceback (most recent call last):
  File "/home/pi/.local/lib/python3.5/site-packages/flask/app.py", line 1982, in wsgi_app
    response = self.full_dispatch_request()
  File "/home/pi/.local/lib/python3.5/site-packages/flask/app.py", line 1614, in full_dispatch_request
    rv = self.handle_user_exception(e)
  File "/home/pi/.local/lib/python3.5/site-packages/flask/app.py", line 1517, in handle_user_exception
    reraise(exc_type, exc_value, tb)
  File "/home/pi/.local/lib/python3.5/site-packages/flask/_compat.py", line 33, in reraise
    raise value
  File "/home/pi/.local/lib/python3.5/site-packages/flask/app.py", line 1612, in full_dispatch_request
    rv = self.dispatch_request()
  File "/home/pi/.local/lib/python3.5/site-packages/flask/app.py", line 1598, in dispatch_request
    return self.view_functions[rule.endpoint](**req.view_args)
  File "/home/pi/Documents/pitemp/app/pitemp_api.py", line 30, in get_status
    system_status = pt.get_system_status()
  File "/home/pi/Documents/pitemp/app/pitemp_lib.py", line 220, in get_system_status
    'system_memory':system_memory['cpu_mem'],
NameError: name 'system_memory' is not defined
[2020-08-18 22:01:35 -0400] [22218] [INFO] Worker reloading: /home/pi/Documents/pitemp/app/pitemp_lib.py modified
[2020-08-18 22:01:35 -0400] [22218] [INFO] Worker exiting (pid: 22218)
[2020-08-18 22:01:35 -0400] [22243] [INFO] Booting worker with pid: 22243
[2020-08-18 22:01:40 -0400] [22243] [DEBUG] GET /api/1.0/status
[2020-08-20 21:39:27 -0400] [22243] [INFO] Worker reloading: /home/pi/Documents/pitemp/app/pitemp_lib.py modified
[2020-08-20 21:39:27 -0400] [22243] [INFO] Worker exiting (pid: 22243)
[2020-08-20 21:39:27 -0400] [28343] [INFO] Booting worker with pid: 28343
[2020-08-20 21:43:43 -0400] [28343] [INFO] Worker exiting (pid: 28343)
[2020-08-20 21:43:44 -0400] [28440] [INFO] Booting worker with pid: 28440
[2020-08-20 21:44:03 -0400] [21837] [INFO] Handling signal: term
[2020-08-20 21:44:03 -0400] [28440] [INFO] Worker exiting (pid: 28440)
[2020-08-20 21:44:03 -0400] [21837] [INFO] Shutting down: Master
[2020-08-20 21:45:43 -0400] [28493] [DEBUG] Current configuration:
  config: None
  raw_paste_global_conf: []
  bind: ['0.0.0.0:10500']
  accesslog: gunicorn_access.log
  capture_output: False
  syslog_facility: user
  reload: True
  preload_app: False
  raw_env: []
  group: 1000
  worker_connections: 1000
  secure_scheme_headers: {'X-FORWARDED-SSL': 'on', 'X-FORWARDED-PROTO': 'https', 'X-FORWARDED-PROTOCOL': 'ssl'}
  keepalive: 2
  reuse_port: False
  disable_redirect_access_to_syslog: False
  errorlog: gunicorn_error.log
  syslog_addr: udp://localhost:514
  when_ready: <function WhenReady.when_ready at 0x761e54f8>
  do_handshake_on_connect: False
  access_log_format: %(h)s %(l)s %(u)s %(t)s "%(r)s" %(s)s %(b)s "%(f)s" "%(a)s"
  threads: 1
  max_requests: 0
  pidfile: None
  enable_stdio_inheritance: False
  statsd_host: None
  daemon: False
  initgroups: False
  forwarded_allow_ips: ['127.0.0.1']
  proc_name: None
  workers: 1
  chdir: /home/pi/Documents/pitemp/app
  proxy_protocol: False
  proxy_allow_ips: ['127.0.0.1']
  ciphers: None
  timeout: 120
  graceful_timeout: 30
  logger_class: gunicorn.glogging.Logger
  statsd_prefix: 
  post_fork: <function Postfork.post_fork at 0x761e5660>
  spew: False
  logconfig: None
  limit_request_fields: 100
  nworkers_changed: <function NumWorkersChanged.nworkers_changed at 0x761e5bb8>
  backlog: 2048
  certfile: None
  worker_abort: <function WorkerAbort.worker_abort at 0x761e5858>
  paste: None
  post_request: <function PostRequest.post_request at 0x761e59c0>
  loglevel: debug
  keyfile: None
  worker_class: sync
  limit_request_line: 4094
  limit_request_field_size: 8190
  on_starting: <function OnStarting.on_starting at 0x761e53d8>
  on_reload: <function OnReload.on_reload at 0x761e5468>
  pre_fork: <function Prefork.pre_fork at 0x761e55d0>
  syslog: False
  syslog_prefix: None
  reload_extra_files: []
  check_config: False
  worker_tmp_dir: None
  pythonpath: None
  worker_int: <function WorkerInt.worker_int at 0x761e57c8>
  pre_exec: <function PreExec.pre_exec at 0x761e58e8>
  pre_request: <function PreRequest.pre_request at 0x761e5978>
  worker_exit: <function WorkerExit.worker_exit at 0x761e5b28>
  user: 1000
  umask: 0
  tmp_upload_dir: None
  max_requests_jitter: 0
  strip_header_spaces: False
  ssl_version: 2
  cert_reqs: 0
  reload_engine: auto
  ca_certs: None
  post_worker_init: <function PostWorkerInit.post_worker_init at 0x761e5738>
  default_proc_name: pitemp_api
  child_exit: <function ChildExit.child_exit at 0x761e5a98>
  on_exit: <function OnExit.on_exit at 0x761e5c48>
  sendfile: None
  suppress_ragged_eofs: True
  logconfig_dict: {}
  dogstatsd_tags: 
[2020-08-20 21:45:43 -0400] [28493] [INFO] Starting gunicorn 20.0.4
[2020-08-20 21:45:43 -0400] [28493] [DEBUG] Arbiter booted
[2020-08-20 21:45:43 -0400] [28493] [INFO] Listening at: http://0.0.0.0:10500 (28493)
[2020-08-20 21:45:43 -0400] [28493] [INFO] Using worker: sync
[2020-08-20 21:45:43 -0400] [28493] [DEBUG] 1 workers
[2020-08-20 21:45:43 -0400] [28497] [INFO] Booting worker with pid: 28497
[2020-08-20 21:45:43 -0400] [28497] [ERROR] Exception in worker process
Traceback (most recent call last):
  File "/home/pi/.local/lib/python3.5/site-packages/gunicorn/arbiter.py", line 583, in spawn_worker
    worker.init_process()
  File "/home/pi/.local/lib/python3.5/site-packages/gunicorn/workers/base.py", line 119, in init_process
    self.load_wsgi()
  File "/home/pi/.local/lib/python3.5/site-packages/gunicorn/workers/base.py", line 144, in load_wsgi
    self.wsgi = self.app.wsgi()
  File "/home/pi/.local/lib/python3.5/site-packages/gunicorn/app/base.py", line 67, in wsgi
    self.callable = self.load()
  File "/home/pi/.local/lib/python3.5/site-packages/gunicorn/app/wsgiapp.py", line 49, in load
    return self.load_wsgiapp()
  File "/home/pi/.local/lib/python3.5/site-packages/gunicorn/app/wsgiapp.py", line 39, in load_wsgiapp
    return util.import_app(self.app_uri)
  File "/home/pi/.local/lib/python3.5/site-packages/gunicorn/util.py", line 358, in import_app
    mod = importlib.import_module(module)
  File "/usr/lib/python3.5/importlib/__init__.py", line 126, in import_module
    return _bootstrap._gcd_import(name[level:], package, level)
  File "<frozen importlib._bootstrap>", line 986, in _gcd_import
  File "<frozen importlib._bootstrap>", line 969, in _find_and_load
  File "<frozen importlib._bootstrap>", line 958, in _find_and_load_unlocked
  File "<frozen importlib._bootstrap>", line 673, in _load_unlocked
  File "<frozen importlib._bootstrap_external>", line 673, in exec_module
  File "<frozen importlib._bootstrap>", line 222, in _call_with_frames_removed
  File "/home/pi/Documents/pitemp/app/pitemp_api.py", line 1, in <module>
    import settings
  File "/home/pi/Documents/pitemp/app/settings.py", line 20, in <module>
    PINS = PINS.split(',')
AttributeError: 'NoneType' object has no attribute 'split'
[2020-08-20 21:45:43 -0400] [28497] [INFO] Worker exiting (pid: 28497)
[2020-08-20 21:45:43 -0400] [28493] [INFO] Shutting down: Master
[2020-08-20 21:45:43 -0400] [28493] [INFO] Reason: Worker failed to boot.
[2020-08-20 21:46:35 -0400] [28519] [DEBUG] Current configuration:
  limit_request_line: 4094
  chdir: /home/pi/Documents/pitemp/app
  paste: None
  reload: True
  logconfig_dict: {}
  worker_tmp_dir: None
  statsd_prefix: 
  on_starting: <function OnStarting.on_starting at 0x761513d8>
  raw_env: []
  access_log_format: %(h)s %(l)s %(u)s %(t)s "%(r)s" %(s)s %(b)s "%(f)s" "%(a)s"
  pre_request: <function PreRequest.pre_request at 0x76151978>
  forwarded_allow_ips: ['127.0.0.1']
  capture_output: False
  worker_class: sync
  syslog_addr: udp://localhost:514
  backlog: 2048
  child_exit: <function ChildExit.child_exit at 0x76151a98>
  bind: ['0.0.0.0:10500']
  tmp_upload_dir: None
  disable_redirect_access_to_syslog: False
  on_exit: <function OnExit.on_exit at 0x76151c48>
  workers: 1
  errorlog: gunicorn_error.log
  enable_stdio_inheritance: False
  limit_request_fields: 100
  reuse_port: False
  do_handshake_on_connect: False
  pre_fork: <function Prefork.pre_fork at 0x761515d0>
  strip_header_spaces: False
  logger_class: gunicorn.glogging.Logger
  graceful_timeout: 30
  post_fork: <function Postfork.post_fork at 0x76151660>
  worker_connections: 1000
  keyfile: None
  syslog_facility: user
  default_proc_name: pitemp_api
  reload_extra_files: []
  pythonpath: None
  accesslog: gunicorn_access.log
  limit_request_field_size: 8190
  statsd_host: None
  dogstatsd_tags: 
  on_reload: <function OnReload.on_reload at 0x76151468>
  worker_exit: <function WorkerExit.worker_exit at 0x76151b28>
  preload_app: False
  max_requests_jitter: 0
  config: None
  proc_name: None
  loglevel: debug
  proxy_allow_ips: ['127.0.0.1']
  syslog_prefix: None
  threads: 1
  worker_int: <function WorkerInt.worker_int at 0x761517c8>
  sendfile: None
  pidfile: None
  ssl_version: 2
  spew: False
  timeout: 120
  when_ready: <function WhenReady.when_ready at 0x761514f8>
  worker_abort: <function WorkerAbort.worker_abort at 0x76151858>
  daemon: False
  initgroups: False
  proxy_protocol: False
  certfile: None
  reload_engine: auto
  logconfig: None
  group: 1000
  cert_reqs: 0
  suppress_ragged_eofs: True
  ciphers: None
  keepalive: 2
  pre_exec: <function PreExec.pre_exec at 0x761518e8>
  user: 1000
  umask: 0
  secure_scheme_headers: {'X-FORWARDED-PROTOCOL': 'ssl', 'X-FORWARDED-SSL': 'on', 'X-FORWARDED-PROTO': 'https'}
  nworkers_changed: <function NumWorkersChanged.nworkers_changed at 0x76151bb8>
  syslog: False
  raw_paste_global_conf: []
  post_request: <function PostRequest.post_request at 0x761519c0>
  check_config: False
  ca_certs: None
  max_requests: 0
  post_worker_init: <function PostWorkerInit.post_worker_init at 0x76151738>
[2020-08-20 21:46:35 -0400] [28519] [INFO] Starting gunicorn 20.0.4
[2020-08-20 21:46:35 -0400] [28519] [DEBUG] Arbiter booted
[2020-08-20 21:46:35 -0400] [28519] [INFO] Listening at: http://0.0.0.0:10500 (28519)
[2020-08-20 21:46:35 -0400] [28519] [INFO] Using worker: sync
[2020-08-20 21:46:35 -0400] [28537] [INFO] Booting worker with pid: 28537
[2020-08-20 21:46:35 -0400] [28519] [DEBUG] 1 workers
[2020-08-20 21:48:19 -0400] [28537] [DEBUG] GET /api/1.0/status
[2020-08-20 21:50:50 -0400] [28537] [INFO] Worker reloading: /home/pi/Documents/pitemp/app/pitemp_lib.py modified
[2020-08-20 21:50:50 -0400] [28537] [INFO] Worker exiting (pid: 28537)
[2020-08-20 21:50:50 -0400] [28565] [INFO] Booting worker with pid: 28565
[2020-08-20 21:51:32 -0400] [28565] [DEBUG] GET /api/1.0/status
[2020-08-20 21:59:10 -0400] [28519] [INFO] Handling signal: hup
[2020-08-20 21:59:10 -0400] [28519] [INFO] Hang up: Master
[2020-08-20 21:59:10 -0400] [28519] [DEBUG] Current configuration:
  limit_request_line: 4094
  chdir: /home/pi/Documents/pitemp/app
  paste: None
  reload: True
  logconfig_dict: {}
  worker_tmp_dir: None
  statsd_prefix: 
  on_starting: <function OnStarting.on_starting at 0x761513d8>
  raw_env: []
  access_log_format: %(h)s %(l)s %(u)s %(t)s "%(r)s" %(s)s %(b)s "%(f)s" "%(a)s"
  pre_request: <function PreRequest.pre_request at 0x76151978>
  forwarded_allow_ips: ['127.0.0.1']
  capture_output: False
  worker_class: sync
  syslog_addr: udp://localhost:514
  backlog: 2048
  child_exit: <function ChildExit.child_exit at 0x76151a98>
  bind: ['0.0.0.0:10500']
  tmp_upload_dir: None
  disable_redirect_access_to_syslog: False
  on_exit: <function OnExit.on_exit at 0x76151c48>
  workers: 1
  errorlog: gunicorn_error.log
  enable_stdio_inheritance: False
  limit_request_fields: 100
  reuse_port: False
  do_handshake_on_connect: False
  pre_fork: <function Prefork.pre_fork at 0x761515d0>
  strip_header_spaces: False
  logger_class: gunicorn.glogging.Logger
  graceful_timeout: 30
  post_fork: <function Postfork.post_fork at 0x76151660>
  worker_connections: 1000
  keyfile: None
  syslog_facility: user
  default_proc_name: pitemp_api
  reload_extra_files: []
  pythonpath: None
  accesslog: gunicorn_access.log
  limit_request_field_size: 8190
  statsd_host: None
  dogstatsd_tags: 
  on_reload: <function OnReload.on_reload at 0x76151468>
  worker_exit: <function WorkerExit.worker_exit at 0x76151b28>
  preload_app: False
  max_requests_jitter: 0
  config: None
  proc_name: None
  loglevel: debug
  proxy_allow_ips: ['127.0.0.1']
  syslog_prefix: None
  threads: 1
  worker_int: <function WorkerInt.worker_int at 0x761517c8>
  sendfile: None
  pidfile: None
  ssl_version: 2
  spew: False
  timeout: 120
  when_ready: <function WhenReady.when_ready at 0x761514f8>
  worker_abort: <function WorkerAbort.worker_abort at 0x76151858>
  daemon: False
  initgroups: False
  proxy_protocol: False
  certfile: None
  reload_engine: auto
  logconfig: None
  group: 1000
  cert_reqs: 0
  suppress_ragged_eofs: True
  ciphers: None
  keepalive: 2
  pre_exec: <function PreExec.pre_exec at 0x761518e8>
  user: 1000
  umask: 0
  secure_scheme_headers: {'X-FORWARDED-PROTOCOL': 'ssl', 'X-FORWARDED-SSL': 'on', 'X-FORWARDED-PROTO': 'https'}
  nworkers_changed: <function NumWorkersChanged.nworkers_changed at 0x76151bb8>
  syslog: False
  raw_paste_global_conf: []
  post_request: <function PostRequest.post_request at 0x761519c0>
  check_config: False
  ca_certs: None
  max_requests: 0
  post_worker_init: <function PostWorkerInit.post_worker_init at 0x76151738>
[2020-08-20 21:59:10 -0400] [28519] [INFO] Handling signal: hup
[2020-08-20 21:59:10 -0400] [28519] [INFO] Hang up: Master
[2020-08-20 21:59:10 -0400] [28664] [INFO] Booting worker with pid: 28664
[2020-08-20 21:59:10 -0400] [28519] [DEBUG] Current configuration:
  limit_request_line: 4094
  chdir: /home/pi/Documents/pitemp/app
  paste: None
  reload: True
  logconfig_dict: {}
  worker_tmp_dir: None
  statsd_prefix: 
  on_starting: <function OnStarting.on_starting at 0x761513d8>
  raw_env: []
  access_log_format: %(h)s %(l)s %(u)s %(t)s "%(r)s" %(s)s %(b)s "%(f)s" "%(a)s"
  pre_request: <function PreRequest.pre_request at 0x76151978>
  forwarded_allow_ips: ['127.0.0.1']
  capture_output: False
  worker_class: sync
  syslog_addr: udp://localhost:514
  backlog: 2048
  child_exit: <function ChildExit.child_exit at 0x76151a98>
  bind: ['0.0.0.0:10500']
  tmp_upload_dir: None
  disable_redirect_access_to_syslog: False
  on_exit: <function OnExit.on_exit at 0x76151c48>
  workers: 1
  errorlog: gunicorn_error.log
  enable_stdio_inheritance: False
  limit_request_fields: 100
  reuse_port: False
  do_handshake_on_connect: False
  pre_fork: <function Prefork.pre_fork at 0x761515d0>
  strip_header_spaces: False
  logger_class: gunicorn.glogging.Logger
  graceful_timeout: 30
  post_fork: <function Postfork.post_fork at 0x76151660>
  worker_connections: 1000
  keyfile: None
  syslog_facility: user
  default_proc_name: pitemp_api
  reload_extra_files: []
  pythonpath: None
  accesslog: gunicorn_access.log
  limit_request_field_size: 8190
  statsd_host: None
  dogstatsd_tags: 
  on_reload: <function OnReload.on_reload at 0x76151468>
  worker_exit: <function WorkerExit.worker_exit at 0x76151b28>
  preload_app: False
  max_requests_jitter: 0
  config: None
  proc_name: None
  loglevel: debug
  proxy_allow_ips: ['127.0.0.1']
  syslog_prefix: None
  threads: 1
  worker_int: <function WorkerInt.worker_int at 0x761517c8>
  sendfile: None
  pidfile: None
  ssl_version: 2
  spew: False
  timeout: 120
  when_ready: <function WhenReady.when_ready at 0x761514f8>
  worker_abort: <function WorkerAbort.worker_abort at 0x76151858>
  daemon: False
  initgroups: False
  proxy_protocol: False
  certfile: None
  reload_engine: auto
  logconfig: None
  group: 1000
  cert_reqs: 0
  suppress_ragged_eofs: True
  ciphers: None
  keepalive: 2
  pre_exec: <function PreExec.pre_exec at 0x761518e8>
  user: 1000
  umask: 0
  secure_scheme_headers: {'X-FORWARDED-PROTOCOL': 'ssl', 'X-FORWARDED-SSL': 'on', 'X-FORWARDED-PROTO': 'https'}
  nworkers_changed: <function NumWorkersChanged.nworkers_changed at 0x76151bb8>
  syslog: False
  raw_paste_global_conf: []
  post_request: <function PostRequest.post_request at 0x761519c0>
  check_config: False
  ca_certs: None
  max_requests: 0
  post_worker_init: <function PostWorkerInit.post_worker_init at 0x76151738>
[2020-08-20 21:59:10 -0400] [28665] [INFO] Booting worker with pid: 28665
[2020-08-20 21:59:11 -0400] [28664] [INFO] Worker exiting (pid: 28664)
[2020-08-21 17:31:30 -0400] [28665] [DEBUG] GET /api/1.0/status
[2020-08-21 18:00:15 -0400] [28665] [INFO] Worker reloading: /home/pi/Documents/pitemp/app/pitemp_lib.py modified
[2020-08-21 18:00:15 -0400] [28665] [INFO] Worker exiting (pid: 28665)
[2020-08-21 18:00:16 -0400] [31357] [INFO] Booting worker with pid: 31357
[2020-08-21 21:18:29 -0400] [31357] [INFO] Worker reloading: /home/pi/Documents/pitemp/app/pitemp_lib.py modified
[2020-08-21 21:18:29 -0400] [31357] [INFO] Worker exiting (pid: 31357)
[2020-08-21 21:18:30 -0400] [31808] [INFO] Booting worker with pid: 31808
[2020-08-21 21:28:33 -0400] [31808] [INFO] Worker reloading: /home/pi/Documents/pitemp/app/pitemp_lib.py modified
[2020-08-21 21:28:33 -0400] [31808] [INFO] Worker exiting (pid: 31808)
[2020-08-21 21:28:34 -0400] [31823] [INFO] Booting worker with pid: 31823
[2020-08-21 21:32:50 -0400] [31823] [INFO] Worker reloading: /home/pi/Documents/pitemp/app/pitemp_lib.py modified
[2020-08-21 21:32:50 -0400] [31823] [INFO] Worker exiting (pid: 31823)
[2020-08-21 21:32:50 -0400] [31845] [INFO] Booting worker with pid: 31845
[2020-08-21 21:41:36 -0400] [31845] [INFO] Worker reloading: /home/pi/Documents/pitemp/app/pitemp_lib.py modified
[2020-08-21 21:41:36 -0400] [31845] [INFO] Worker exiting (pid: 31845)
[2020-08-21 21:41:37 -0400] [31864] [INFO] Booting worker with pid: 31864
[2020-08-21 21:58:28 -0400] [31864] [INFO] Worker reloading: /home/pi/Documents/pitemp/app/pitemp_lib.py modified
[2020-08-21 21:58:28 -0400] [31864] [INFO] Worker exiting (pid: 31864)
[2020-08-21 21:58:28 -0400] [31891] [INFO] Booting worker with pid: 31891
[2020-08-21 21:59:00 -0400] [31891] [DEBUG] GET /api/1.0/status
[2020-08-21 21:59:32 -0400] [31891] [INFO] Worker reloading: /home/pi/Documents/pitemp/app/pitemp_lib.py modified
[2020-08-21 21:59:32 -0400] [31891] [INFO] Worker exiting (pid: 31891)
[2020-08-21 21:59:32 -0400] [31915] [INFO] Booting worker with pid: 31915
[2020-08-21 21:59:37 -0400] [31915] [DEBUG] GET /api/1.0/status
[2020-08-21 22:16:58 -0400] [31915] [INFO] Worker reloading: /home/pi/Documents/pitemp/app/pitemp_lib.py modified
[2020-08-21 22:16:58 -0400] [31915] [INFO] Worker exiting (pid: 31915)
[2020-08-21 22:16:58 -0400] [31983] [INFO] Booting worker with pid: 31983
[2020-08-21 22:19:07 -0400] [31983] [DEBUG] GET /api/1.0/status
[2020-08-21 22:19:07,887] ERROR in app: Exception on /api/1.0/status [GET]
Traceback (most recent call last):
  File "/home/pi/.local/lib/python3.5/site-packages/flask/app.py", line 1982, in wsgi_app
    response = self.full_dispatch_request()
  File "/home/pi/.local/lib/python3.5/site-packages/flask/app.py", line 1614, in full_dispatch_request
    rv = self.handle_user_exception(e)
  File "/home/pi/.local/lib/python3.5/site-packages/flask/app.py", line 1517, in handle_user_exception
    reraise(exc_type, exc_value, tb)
  File "/home/pi/.local/lib/python3.5/site-packages/flask/_compat.py", line 33, in reraise
    raise value
  File "/home/pi/.local/lib/python3.5/site-packages/flask/app.py", line 1612, in full_dispatch_request
    rv = self.dispatch_request()
  File "/home/pi/.local/lib/python3.5/site-packages/flask/app.py", line 1598, in dispatch_request
    return self.view_functions[rule.endpoint](**req.view_args)
  File "/home/pi/Documents/pitemp/app/pitemp_api.py", line 30, in get_status
    system_status = pt.get_system_status()
  File "/home/pi/Documents/pitemp/app/pitemp_lib.py", line 222, in get_system_status
    'system_memory':memory[2],
IndexError: list index out of range
[2020-08-21 22:19:54 -0400] [31983] [INFO] Worker reloading: /home/pi/Documents/pitemp/app/pitemp_lib.py modified
[2020-08-21 22:19:54 -0400] [31983] [INFO] Worker exiting (pid: 31983)
[2020-08-21 22:19:54 -0400] [32023] [INFO] Booting worker with pid: 32023
[2020-08-21 22:20:04 -0400] [32023] [DEBUG] GET /api/1.0/status
[2020-08-21 22:20:04,303] ERROR in app: Exception on /api/1.0/status [GET]
Traceback (most recent call last):
  File "/home/pi/.local/lib/python3.5/site-packages/flask/app.py", line 1982, in wsgi_app
    response = self.full_dispatch_request()
  File "/home/pi/.local/lib/python3.5/site-packages/flask/app.py", line 1614, in full_dispatch_request
    rv = self.handle_user_exception(e)
  File "/home/pi/.local/lib/python3.5/site-packages/flask/app.py", line 1517, in handle_user_exception
    reraise(exc_type, exc_value, tb)
  File "/home/pi/.local/lib/python3.5/site-packages/flask/_compat.py", line 33, in reraise
    raise value
  File "/home/pi/.local/lib/python3.5/site-packages/flask/app.py", line 1612, in full_dispatch_request
    rv = self.dispatch_request()
  File "/home/pi/.local/lib/python3.5/site-packages/flask/app.py", line 1598, in dispatch_request
    return self.view_functions[rule.endpoint](**req.view_args)
  File "/home/pi/Documents/pitemp/app/pitemp_api.py", line 30, in get_status
    system_status = pt.get_system_status()
  File "/home/pi/Documents/pitemp/app/pitemp_lib.py", line 222, in get_system_status
    'system_memory':memory[2],
IndexError: list index out of range
[2020-08-21 22:20:05 -0400] [32023] [DEBUG] GET /api/1.0/status
[2020-08-21 22:20:06,112] ERROR in app: Exception on /api/1.0/status [GET]
Traceback (most recent call last):
  File "/home/pi/.local/lib/python3.5/site-packages/flask/app.py", line 1982, in wsgi_app
    response = self.full_dispatch_request()
  File "/home/pi/.local/lib/python3.5/site-packages/flask/app.py", line 1614, in full_dispatch_request
    rv = self.handle_user_exception(e)
  File "/home/pi/.local/lib/python3.5/site-packages/flask/app.py", line 1517, in handle_user_exception
    reraise(exc_type, exc_value, tb)
  File "/home/pi/.local/lib/python3.5/site-packages/flask/_compat.py", line 33, in reraise
    raise value
  File "/home/pi/.local/lib/python3.5/site-packages/flask/app.py", line 1612, in full_dispatch_request
    rv = self.dispatch_request()
  File "/home/pi/.local/lib/python3.5/site-packages/flask/app.py", line 1598, in dispatch_request
    return self.view_functions[rule.endpoint](**req.view_args)
  File "/home/pi/Documents/pitemp/app/pitemp_api.py", line 30, in get_status
    system_status = pt.get_system_status()
  File "/home/pi/Documents/pitemp/app/pitemp_lib.py", line 222, in get_system_status
    'system_memory':memory[2],
IndexError: list index out of range
[2020-08-21 22:25:22 -0400] [32023] [INFO] Worker reloading: /home/pi/Documents/pitemp/app/pitemp_lib.py modified
[2020-08-21 22:25:22 -0400] [32023] [INFO] Worker exiting (pid: 32023)
[2020-08-21 22:25:22 -0400] [32079] [INFO] Booting worker with pid: 32079
[2020-08-21 22:25:45 -0400] [32079] [DEBUG] GET /api/1.0/status
[2020-08-21 22:25:45,551] ERROR in app: Exception on /api/1.0/status [GET]
Traceback (most recent call last):
  File "/home/pi/.local/lib/python3.5/site-packages/flask/app.py", line 1982, in wsgi_app
    response = self.full_dispatch_request()
  File "/home/pi/.local/lib/python3.5/site-packages/flask/app.py", line 1614, in full_dispatch_request
    rv = self.handle_user_exception(e)
  File "/home/pi/.local/lib/python3.5/site-packages/flask/app.py", line 1517, in handle_user_exception
    reraise(exc_type, exc_value, tb)
  File "/home/pi/.local/lib/python3.5/site-packages/flask/_compat.py", line 33, in reraise
    raise value
  File "/home/pi/.local/lib/python3.5/site-packages/flask/app.py", line 1612, in full_dispatch_request
    rv = self.dispatch_request()
  File "/home/pi/.local/lib/python3.5/site-packages/flask/app.py", line 1598, in dispatch_request
    return self.view_functions[rule.endpoint](**req.view_args)
  File "/home/pi/Documents/pitemp/app/pitemp_api.py", line 30, in get_status
    system_status = pt.get_system_status()
  File "/home/pi/Documents/pitemp/app/pitemp_lib.py", line 223, in get_system_status
    'system_memory':memory[2],
IndexError: list index out of range
[2020-08-21 22:26:23 -0400] [32079] [INFO] Worker reloading: /home/pi/Documents/pitemp/app/pitemp_lib.py modified
[2020-08-21 22:26:23 -0400] [32079] [INFO] Worker exiting (pid: 32079)
[2020-08-21 22:26:23 -0400] [32105] [INFO] Booting worker with pid: 32105
[2020-08-21 22:26:43 -0400] [32105] [INFO] Worker reloading: /home/pi/Documents/pitemp/app/pitemp_lib.py modified
[2020-08-21 22:26:43 -0400] [32105] [INFO] Worker exiting (pid: 32105)
[2020-08-21 22:26:43 -0400] [32109] [INFO] Booting worker with pid: 32109
[2020-08-21 22:26:50 -0400] [32109] [DEBUG] GET /api/1.0/status
[2020-08-21 22:27:15 -0400] [32109] [INFO] Worker reloading: /home/pi/Documents/pitemp/app/pitemp_lib.py modified
[2020-08-21 22:27:15 -0400] [32109] [INFO] Worker exiting (pid: 32109)
[2020-08-21 22:27:15 -0400] [32133] [INFO] Booting worker with pid: 32133
[2020-08-21 22:29:55 -0400] [32133] [DEBUG] GET /api/1.0/config
[2020-08-21 22:35:33 -0400] [32133] [DEBUG] GET /api/1.0/data
[2020-08-21 22:35:33,175] ERROR in app: Exception on /api/1.0/data [GET]
Traceback (most recent call last):
  File "/home/pi/.local/lib/python3.5/site-packages/flask/app.py", line 1982, in wsgi_app
    response = self.full_dispatch_request()
  File "/home/pi/.local/lib/python3.5/site-packages/flask/app.py", line 1614, in full_dispatch_request
    rv = self.handle_user_exception(e)
  File "/home/pi/.local/lib/python3.5/site-packages/flask/app.py", line 1517, in handle_user_exception
    reraise(exc_type, exc_value, tb)
  File "/home/pi/.local/lib/python3.5/site-packages/flask/_compat.py", line 33, in reraise
    raise value
  File "/home/pi/.local/lib/python3.5/site-packages/flask/app.py", line 1612, in full_dispatch_request
    rv = self.dispatch_request()
  File "/home/pi/.local/lib/python3.5/site-packages/flask/app.py", line 1598, in dispatch_request
    return self.view_functions[rule.endpoint](**req.view_args)
  File "/home/pi/Documents/pitemp/app/pitemp_api.py", line 59, in get_data
    return jsonify(pt.db_read())
TypeError: db_read() takes 0 positional arguments but 1 was given
[2020-08-21 22:36:39 -0400] [32133] [INFO] Worker reloading: /home/pi/Documents/pitemp/app/pitemp_api.py modified
[2020-08-21 22:36:39 -0400] [32133] [INFO] Worker exiting (pid: 32133)
[2020-08-21 22:36:39 -0400] [32158] [INFO] Booting worker with pid: 32158
[2020-08-21 22:40:44 -0400] [32158] [INFO] Worker reloading: /home/pi/Documents/pitemp/app/settings.py modified
[2020-08-21 22:40:44 -0400] [32158] [INFO] Worker exiting (pid: 32158)
[2020-08-21 22:40:44 -0400] [32173] [INFO] Booting worker with pid: 32173
[2020-08-21 22:44:50 -0400] [32173] [INFO] Worker reloading: /home/pi/Documents/pitemp/app/pitemp_api.py modified
[2020-08-21 22:44:50 -0400] [32173] [INFO] Worker exiting (pid: 32173)
[2020-08-21 22:44:51 -0400] [32179] [INFO] Booting worker with pid: 32179
[2020-08-21 22:44:51 -0400] [32179] [ERROR] invalid syntax (pitemp_lib.py, line 274)
Traceback (most recent call last):
  File "/home/pi/.local/lib/python3.5/site-packages/gunicorn/workers/base.py", line 144, in load_wsgi
    self.wsgi = self.app.wsgi()
  File "/home/pi/.local/lib/python3.5/site-packages/gunicorn/app/base.py", line 67, in wsgi
    self.callable = self.load()
  File "/home/pi/.local/lib/python3.5/site-packages/gunicorn/app/wsgiapp.py", line 49, in load
    return self.load_wsgiapp()
  File "/home/pi/.local/lib/python3.5/site-packages/gunicorn/app/wsgiapp.py", line 39, in load_wsgiapp
    return util.import_app(self.app_uri)
  File "/home/pi/.local/lib/python3.5/site-packages/gunicorn/util.py", line 358, in import_app
    mod = importlib.import_module(module)
  File "/usr/lib/python3.5/importlib/__init__.py", line 126, in import_module
    return _bootstrap._gcd_import(name[level:], package, level)
  File "<frozen importlib._bootstrap>", line 986, in _gcd_import
  File "<frozen importlib._bootstrap>", line 969, in _find_and_load
  File "<frozen importlib._bootstrap>", line 958, in _find_and_load_unlocked
  File "<frozen importlib._bootstrap>", line 673, in _load_unlocked
  File "<frozen importlib._bootstrap_external>", line 673, in exec_module
  File "<frozen importlib._bootstrap>", line 222, in _call_with_frames_removed
  File "/home/pi/Documents/pitemp/app/pitemp_api.py", line 2, in <module>
    from pitemp_lib import pitemp
  File "/home/pi/Documents/pitemp/app/pitemp_lib.py", line 274
    def write_config
                   ^
SyntaxError: invalid syntax
[2020-08-21 22:44:51 -0400] [32179] [ERROR] Exception in worker process
Traceback (most recent call last):
  File "/home/pi/.local/lib/python3.5/site-packages/gunicorn/workers/base.py", line 144, in load_wsgi
    self.wsgi = self.app.wsgi()
  File "/home/pi/.local/lib/python3.5/site-packages/gunicorn/app/base.py", line 67, in wsgi
    self.callable = self.load()
  File "/home/pi/.local/lib/python3.5/site-packages/gunicorn/app/wsgiapp.py", line 49, in load
    return self.load_wsgiapp()
  File "/home/pi/.local/lib/python3.5/site-packages/gunicorn/app/wsgiapp.py", line 39, in load_wsgiapp
    return util.import_app(self.app_uri)
  File "/home/pi/.local/lib/python3.5/site-packages/gunicorn/util.py", line 358, in import_app
    mod = importlib.import_module(module)
  File "/usr/lib/python3.5/importlib/__init__.py", line 126, in import_module
    return _bootstrap._gcd_import(name[level:], package, level)
  File "<frozen importlib._bootstrap>", line 986, in _gcd_import
  File "<frozen importlib._bootstrap>", line 969, in _find_and_load
  File "<frozen importlib._bootstrap>", line 958, in _find_and_load_unlocked
  File "<frozen importlib._bootstrap>", line 673, in _load_unlocked
  File "<frozen importlib._bootstrap_external>", line 673, in exec_module
  File "<frozen importlib._bootstrap>", line 222, in _call_with_frames_removed
  File "/home/pi/Documents/pitemp/app/pitemp_api.py", line 2, in <module>
    from pitemp_lib import pitemp
  File "/home/pi/Documents/pitemp/app/pitemp_lib.py", line 274
    def write_config
                   ^
SyntaxError: invalid syntax

During handling of the above exception, another exception occurred:

Traceback (most recent call last):
  File "/home/pi/.local/lib/python3.5/site-packages/gunicorn/arbiter.py", line 583, in spawn_worker
    worker.init_process()
  File "/home/pi/.local/lib/python3.5/site-packages/gunicorn/workers/base.py", line 119, in init_process
    self.load_wsgi()
  File "/home/pi/.local/lib/python3.5/site-packages/gunicorn/workers/base.py", line 157, in load_wsgi
    self.reloader.add_extra_file(exc_val.filename)
AttributeError: 'NoneType' object has no attribute 'add_extra_file'
[2020-08-21 22:44:51 -0400] [32179] [INFO] Worker exiting (pid: 32179)
[2020-08-21 22:44:51 -0400] [28519] [INFO] Shutting down: Master
[2020-08-21 22:44:51 -0400] [28519] [INFO] Reason: Worker failed to boot.
